Workbook

Sheet COVER
B3: Table of Content
N8: ABREVATIONS | R8: FULL FORMS
D10: DASHBOARD | N10: IR | R10: INVOICE RECORD
N14: CT | R14: CREDIT TRACKER
D15: IR
N18: PR | R18: PAYMENT REGISTER
D19: CT
N21: ARD | R21: ACCOUNTS RECIEVALE DATA
D23: PR
N24: RS | R24: Recievable Summary
M26: Note*
N27: This model Assumes that the payments of the clients are paid in advance for 50%.
N29: If there is an amount that needs to be added just add onto the Payment
D30: ARD | N30: register under Input amount. So that the model can recalculate all
N31: the other transactions and amounts simultaneiously.
N33: The date of deposit is hard coded as the model assumes that the payer
N34: has paid the amount In one or 2 working days.
D36: RS | N36: This model also has a limited date span so inorder to add more in voices
N37: as well as dates do put onto a separate coloums
N39: At 31 days the sheet shows 1 day overdue but still charges nothing it charges
N40: late due on 32 day.

Sheet DASHBOARD
H2: DASHBOARD
J8: Row Labels | K8: Sum of Deposit Amount | M8: Row Labels | N8: Sum of Amounts Paid | Q8: Row Labels | R8: Sum of Outstanding Amount | S8: Sum of Amounts Paid | T8: Sum of Deposit Amount | V8: Row Labels | W8: Count of Invoice Number
J9: Consulting services | K9: 7511.625 | M9: Consulting services | N9: 7674.9175 | Q9: Consulting services | R9: 7511.625 | S9: 7674.9175 | T9: 7511.625 | V9: Consulting services | W9: 10
J10: Equipment purchase | K10: 8698.375 | M10: Equipment purchase | N10: 8704.5275 | Q10: Equipment purchase | R10: 6483.125 | S10: 8704.5275 | T10: 8698.375 | V10: Equipment purchase | W10: 10
J11: Maintenance services | K11: 3451.125 | M11: Maintenance services | N11: 3603.4062 | Q11: Maintenance services | R11: 2911.125 | S11: 3603.4062 | T11: 3451.125 | V11: Maintenance services | W11: 10
J12: Marketing services | K12: 5351.525 | M12: Marketing services | N12: 5615.955 | Q12: Marketing services | R12: 4761.525 | S12: 5615.955 | T12: 5351.525 | V12: Marketing services | W12: 10
J13: Monthly subscription | K13: 5056 | M13: Monthly subscription | N13: 5306.2337 | Q13: Monthly subscription | R13: 2921 | S13: 5306.2337 | T13: 5056 | V13: Monthly subscription | W13: 10
J14: Office supplies | K14: 4443.375 | M14: Office supplies | N14: 4462.0125 | Q14: Office supplies | R14: 3718.375 | S14: 4462.0125 | T14: 4443.375 | V14: Office supplies | W14: 10
J15: Project delivery | K15: 7191.025 | M15: Project delivery | N15: 7794.652 | Q15: Project delivery | R15: 7191.025 | S15: 7794.652 | T15: 7191.025 | V15: Project delivery | W15: 10
J16: Software licence | K16: 8508.875 | M16: Software licence | N16: 9039.8762 | Q16: Software licence | R16: 6833.875 | S16: 9039.8762 | T16: 8508.875 | V16: Software licence | W16: 10
J17: Stationery order | K17: 4871.375 | M17: Stationery order | N17: 4918.0163 | Q17: Stationery order | R17: 4605.875 | S17: 4918.0163 | T17: 4871.375 | V17: Stationery order | W17: 10
J18: Training services | K18: 6196.125 | M18: Training services | N18: 6359.2788 | Q18: Training services | R18: 4271.625 | S18: 6359.2788 | T18: 6196.125 | V18: Training services | W18: 10
J19: Grand Total | K19: 61279.425 | M19: Grand Total | N19: 63478.876 | Q19: Grand Total | R19: 51209.175 | S19: 63478.876 | T19: 61279.425 | V19: Grand Total | W19: 100
J23: Total Amount | L23: =SUM(PR!N6:N105) -> 63478.876
O24: Accounts Recievable Summary | S24: Total Invoice | U24: =COUNTA(IR!A2:A101) -> 100
J25: Total Deposit Amount | L25: =SUM(PR!L6:L105) -> 61279.425
O26: Paid | Q26: =COUNTIF(Table6[[Status ]],DASHBOARD!O26) -> 8 | S26: Total Invoice Amount | U26: =SUM(IR!$D$2:$D$101) -> 112488.6
J27: Total Outstanding Amount | L27: =SUM(PR!M6:M105) -> 51209.175 | O27: Unpaid | Q27: =COUNTIF(Table6[[Status ]],DASHBOARD!O27) -> 3
O28: Due | Q28: =COUNTIF(Table6[[Status ]],DASHBOARD!O28) -> 89 | S28: Average Invoice Amount | U28: =AVERAGE(IR!D2:D101) -> 1124.886
J29: Average Amount | L29: =AVERAGE(PR!$N$6:$N$105) -> 634.78876
S30: Minimum Invoice Amount | U30: =MIN(IR!$D$2:$D$101) -> 265.5
J31: Minimum Amount | L31: =MIN(PR!$N$6:$N$105) -> 140
P32: Ratio | S32: Maximum Invoice Amount | U32: =MAX(IR!$D$2:$D$101) -> 2850
J33: Maximum Amount | L33: =MAX(PR!$N$6:$N$105) -> 1675 | P33: Paid | Q33: =Q26 -> 8
P34: Due | Q34: =Q28 -> 89
Q35: =Q33/Q34 -> 0.08988764

Sheet IR
A1: Customer Invoice Number | B1: Customer Name | C1: Date of Invoice | D1: Invoice Amount (£) | E1: Note | F1: Payment Reference
A2: INV-2026-001 | B2: Oliver Bennett | C2: 46311 | D2: 450 | E2: Office supplies | F2: PAY-7001
A3: INV-2026-002 | B3: Amelia Carter | C3: 46254 | D3: 1250.5 | E3: Consulting services | F3: PAY-7002
A4: INV-2026-003 | B4: George Mitchell | C4: 46259 | D4: 785.25 | E4: Equipment purchase | F4: PAY-7003
A5: INV-2026-004 | B5: Isla Thompson | C5: 46267 | D5: 320 | E5: Monthly subscription | F5: PAY-7004
A6: INV-2026-005 | B6: Harry Wilson | C6: 46270 | D6: 2100 | E6: Project delivery | F6: PAY-7005
A7: INV-2026-006 | B7: Ava Robinson | C7: 46275 | D7: 675.8 | E7: Marketing services | F7: PAY-7006
A8: INV-2026-007 | B8: Noah Walker | C8: 46277 | D8: 540 | E8: Maintenance services | F8: PAY-7007
A9: INV-2026-008 | B9: Grace Hall | C9: 46280 | D9: 1890.75 | E9: Software licence | F9: PAY-7008
A10: INV-2026-009 | B10: Jack Young | C10: 46283 | D10: 265.5 | E10: Stationery order | F10: PAY-7009
A11: INV-2026-010 | B11: Lily Allen | C11: 46285 | D11: 980 | E11: Training services | F11: PAY-7010
A12: INV-2026-011 | B12: Charlie King | C12: 46287 | D12: 1450 | E12: Consulting services | F12: PAY-7011
A13: INV-2026-012 | B13: Mia Wright | C13: 46290 | D13: 375.25 | E13: Office supplies | F13: PAY-7012
... A101: INV-2026-100 | B101: Victoria Taylor | C101: 46253 | D101: 1285 | E101: Training services | F101: PAY-7100

Sheet PR
B2: PAYMENT REGISTRY
C5: S.NO | D5: Invoice Number | E5: Customer Name | F5: Date of invoice | G5: Invoice Amount | H5: Payment Note | I5: Payment Refence | J5: Input Amount (If paid) | K5: Date of Deposit | L5: Deposit Amount | M5: Outstanding Amount | N5: Amounts Paid
C6: 1 | D6: =IR!$A$2 -> INV-2026-001 | E6: =VLOOKUP(PR!$D6,IR!$A$2:$F$101,2) -> Oliver Bennett | F6: =VLOOKUP(PR!$D6,IR!$A$2:$F$101,3) -> 46311 | G6: =VLOOKUP(PR!$D6,IR!$A$2:$F$101,4) -> 450 | H6: =VLOOKUP(PR!$D6,IR!$A$2:$F$101,5) -> Office supplies | I6: =VLOOKUP(PR!$D6,IR!$A$2:$F$101,6) -> PAY-7001 | K6: =WORKDAY(Table3[[#This Row],[Date of invoice]],2) -> 46315 | L6: =IF(PR!$J6=0,PR!$G6*50%,PR!$J6) -> 225 | M6: =IF(L6=G6,"Paid All",G6-L6) -> 225 | N6: =ARD!L12 -> 225
C7: =C6+1 -> 2 | D7: =IR!A3 -> INV-2026-002 | E7: =VLOOKUP(PR!$D7,IR!$A$2:$F$101,2) -> Amelia Carter | F7: =VLOOKUP(PR!$D7,IR!$A$2:$F$101,3) -> 46254 | G7: =VLOOKUP(PR!$D7,IR!$A$2:$F$101,4) -> 1250.5 | H7: =VLOOKUP(PR!$D7,IR!$A$2:$F$101,5) -> Consulting services | I7: =VLOOKUP(PR!$D7,IR!$A$2:$F$101,6) -> PAY-7002 | K7: =WORKDAY(Table3[[#This Row],[Date of invoice]],2) -> 46258 | L7: =IF(PR!$J7=0,PR!$G7*50%,PR!$J7) -> 625.25 | M7: =IF(L7=G7,"Paid All",G7-L7) -> 625.25 | N7: =ARD!L13 -> 731.5425
C8: =C7+1 -> 3 | D8: =IR!A4 -> INV-2026-003 | E8: =VLOOKUP(PR!$D8,IR!$A$2:$F$101,2) -> George Mitchell | F8: =VLOOKUP(PR!$D8,IR!$A$2:$F$101,3) -> 46259 | G8: =VLOOKUP(PR!$D8,IR!$A$2:$F$101,4) -> 785.25 | H8: =VLOOKUP(PR!$D8,IR!$A$2:$F$101,5) -> Equipment purchase | I8: =VLOOKUP(PR!$D8,IR!$A$2:$F$101,6) -> PAY-7003 | J8: 785.25 | K8: =WORKDAY(Table3[[#This Row],[Date of invoice]],2) -> 46261 | L8: =IF(PR!$J8=0,PR!$G8*50%,PR!$J8) -> 785.25 | M8: =IF(L8=G8,"Paid All",G8-L8) -> Paid All | N8: =ARD!L14 -> 785.25
C9: =C8+1 -> 4 | D9: =IR!A5 -> INV-2026-004 | E9: =VLOOKUP(PR!$D9,IR!$A$2:$F$101,2) -> Isla Thompson | F9: =VLOOKUP(PR!$D9,IR!$A$2:$F$101,3) -> 46267 | G9: =VLOOKUP(PR!$D9,IR!$A$2:$F$101,4) -> 320 | H9: =VLOOKUP(PR!$D9,IR!$A$2:$F$101,5) -> Monthly subscription | I9: =VLOOKUP(PR!$D9,IR!$A$2:$F$101,6) -> PAY-7004 | K9: =WORKDAY(Table3[[#This Row],[Date of invoice]],2) -> 46269 | L9: =IF(PR!$J9=0,PR!$G9*50%,PR!$J9) -> 160 | M9: =IF(L9=G9,"Paid All",G9-L9) -> 160 | N9: =ARD!L15 -> 172.8
C10: =C9+1 -> 5 | D10: =IR!A6 -> INV-2026-005 | E10: =VLOOKUP(PR!$D10,IR!$A$2:$F$101,2) -> Harry Wilson | F10: =VLOOKUP(PR!$D10,IR!$A$2:$F$101,3) -> 46270 | G10: =VLOOKUP(PR!$D10,IR!$A$2:$F$101,4) -> 2100 | H10: =VLOOKUP(PR!$D10,IR!$A$2:$F$101,5) -> Project delivery | I10: =VLOOKUP(PR!$D10,IR!$A$2:$F$101,6) -> PAY-7005 | K10: =WORKDAY(Table3[[#This Row],[Date of invoice]],2) -> 46273 | L10: =IF(PR!$J10=0,PR!$G10*50%,PR!$J10) -> 1050 | M10: =IF(L10=G10,"Paid All",G10-L10) -> 1050 | N10: =ARD!L16 -> 1134
C11: =C10+1 -> 6 | D11: =IR!A7 -> INV-2026-006 | E11: =VLOOKUP(PR!$D11,IR!$A$2:$F$101,2) -> Ava Robinson | F11: =VLOOKUP(PR!$D11,IR!$A$2:$F$101,3) -> 46275 | G11: =VLOOKUP(PR!$D11,IR!$A$2:$F$101,4) -> 675.8 | H11: =VLOOKUP(PR!$D11,IR!$A$2:$F$101,5) -> Marketing services | I11: =VLOOKUP(PR!$D11,IR!$A$2:$F$101,6) -> PAY-7006 | K11: =WORKDAY(Table3[[#This Row],[Date of invoice]],2) -> 46279 | L11: =IF(PR!$J11=0,PR!$G11*50%,PR!$J11) -> 337.9 | M11: =IF(L11=G11,"Paid All",G11-L11) -> 337.9 | N11: =ARD!L17 -> 354.795
C12: =C11+1 -> 7 | D12: =IR!A8 -> INV-2026-007 | E12: =VLOOKUP(PR!$D12,IR!$A$2:$F$101,2) -> Noah Walker | F12: =VLOOKUP(PR!$D12,IR!$A$2:$F$101,3) -> 46277 | G12: =VLOOKUP(PR!$D12,IR!$A$2:$F$101,4) -> 540 | H12: =VLOOKUP(PR!$D12,IR!$A$2:$F$101,5) -> Maintenance services | I12: =VLOOKUP(PR!$D12,IR!$A$2:$F$101,6) -> PAY-7007 | J12: 540 | K12: =WORKDAY(Table3[[#This Row],[Date of invoice]],2) -> 46280 | L12: =IF(PR!$J12=0,PR!$G12*50%,PR!$J12) -> 540 | M12: =IF(L12=G12,"Paid All",G12-L12) -> Paid All | N12: =ARD!L18 -> 540
C13: =C12+1 -> 8 | D13: =IR!A9 -> INV-2026-008 | E13: =VLOOKUP(PR!$D13,IR!$A$2:$F$101,2) -> Grace Hall | F13: =VLOOKUP(PR!$D13,IR!$A$2:$F$101,3) -> 46280 | G13: =VLOOKUP(PR!$D13,IR!$A$2:$F$101,4) -> 1890.75 | H13: =VLOOKUP(PR!$D13,IR!$A$2:$F$101,5) -> Software licence | I13: =VLOOKUP(PR!$D13,IR!$A$2:$F$101,6) -> PAY-7008 | K13: =WORKDAY(Table3[[#This Row],[Date of invoice]],2) -> 46282 | L13: =IF(PR!$J13=0,PR!$G13*50%,PR!$J13) -> 945.375 | M13: =IF(L13=G13,"Paid All",G13-L13) -> 945.375 | N13: =ARD!L19 -> 964.2825
C14: =C13+1 -> 9 | D14: =IR!A10 -> INV-2026-009 | E14: =VLOOKUP(PR!$D14,IR!$A$2:$F$101,2) -> Jack Young | F14: =VLOOKUP(PR!$D14,IR!$A$2:$F$101,3) -> 46283 | G14: =VLOOKUP(PR!$D14,IR!$A$2:$F$101,4) -> 265.5 | H14: =VLOOKUP(PR!$D14,IR!$A$2:$F$101,5) -> Stationery order | I14: =VLOOKUP(PR!$D14,IR!$A$2:$F$101,6) -> PAY-7009 | J14: 265.5 | K14: =WORKDAY(Table3[[#This Row],[Date of invoice]],2) -> 46287 | L14: =IF(PR!$J14=0,PR!$G14*50%,PR!$J14) -> 265.5 | M14: =IF(L14=G14,"Paid All",G14-L14) -> Paid All | N14: =ARD!L20 -> 265.5
C15: =C14+1 -> 10 | D15: =IR!A11 -> INV-2026-010 | E15: =VLOOKUP(PR!$D15,IR!$A$2:$F$101,2) -> Lily Allen | F15: =VLOOKUP(PR!$D15,IR!$A$2:$F$101,3) -> 46285 | G15: =VLOOKUP(PR!$D15,IR!$A$2:$F$101,4) -> 980 | H15: =VLOOKUP(PR!$D15,IR!$A$2:$F$101,5) -> Training services | I15: =VLOOKUP(PR!$D15,IR!$A$2:$F$101,6) -> PAY-7010 | K15: =WORKDAY(Table3[[#This Row],[Date of invoice]],2) -> 46287 | L15: =IF(PR!$J15=0,PR!$G15*50%,PR!$J15) -> 490 | M15: =IF(L15=G15,"Paid All",G15-L15) -> 490 | N15: =ARD!L21 -> 490
C16: =C15+1 -> 11 | D16: =IR!A12 -> INV-2026-011 | E16: =VLOOKUP(PR!$D16,IR!$A$2:$F$101,2) -> Charlie King | F16: =VLOOKUP(PR!$D16,IR!$A$2:$F$101,3) -> 46287 | G16: =VLOOKUP(PR!$D16,IR!$A$2:$F$101,4) -> 1450 | H16: =VLOOKUP(PR!$D16,IR!$A$2:$F$101,5) -> Consulting services | I16: =VLOOKUP(PR!$D16,IR!$A$2:$F$101,6) -> PAY-7011 | K16: =WORKDAY(Table3[[#This Row],[Date of invoice]],2) -> 46289 | L16: =IF(PR!$J16=0,PR!$G16*50%,PR!$J16) -> 725 | M16: =IF(L16=G16,"Paid All",G16-L16) -> 725 | N16: =ARD!L22 -> 725
C17: =C16+1 -> 12 | D17: =IR!A13 -> INV-2026-012 | E17: =VLOOKUP(PR!$D17,IR!$A$2:$F$101,2) -> Mia Wright | F17: =VLOOKUP(PR!$D17,IR!$A$2:$F$101,3) -> 46290 | G17: =VLOOKUP(PR!$D17,IR!$A$2:$F$101,4) -> 375.25 | H17: =VLOOKUP(PR!$D17,IR!$A$2:$F$101,5) -> Office supplies | I17: =VLOOKUP(PR!$D17,IR!$A$2:$F$101,6) -> PAY-7012 | K17: =WORKDAY(Table3[[#This Row],[Date of invoice]],2) -> 46294 | L17: =IF(PR!$J17=0,PR!$G17*50%,PR!$J17) -> 187.625 | M17: =IF(L17=G17,"Paid All",G17-L17) -> 187.625 | N17: =ARD!L23 -> 187.625
C18: =C17+1 -> 13 | D18: =IR!A14 -> INV-2026-013 | E18: =VLOOKUP(PR!$D18,IR!$A$2:$F$101,2) -> Thomas Scott | F18: =VLOOKUP(PR!$D18,IR!$A$2:$F$101,3) -> 46293 | G18: =VLOOKUP(PR!$D18,IR!$A$2:$F$101,4) -> 2750 | H18: =VLOOKUP(PR!$D18,IR!$A$2:$F$101,5) -> Equipment purchase | I18: =VLOOKUP(PR!$D18,IR!$A$2:$F$101,6) -> PAY-7013 | K18: =WORKDAY(Table3[[#This Row],[Date of invoice]],2) -> 46295 | L18: =IF(PR!$J18=0,PR!$G18*50%,PR!$J18) -> 1375 | M18: =IF(L18=G18,"Paid All",G18-L18) -> 1375 | N18: =ARD!L24 -> 1375
C19: =C18+1 -> 14 | D19: =IR!A15 -> INV-2026-014 | E19: =VLOOKUP(PR!$D19,IR!$A$2:$F$101,2) -> Sophia Green | F19: =VLOOKUP(PR!$D19,IR!$A$2:$F$101,3) -> 46295 | G19: =VLOOKUP(PR!$D19,IR!$A$2:$F$101,4) -> 625 | H19: =VLOOKUP(PR!$D19,IR!$A$2:$F$101,5) -> Monthly subscription | I19: =VLOOKUP(PR!$D19,IR!$A$2:$F$101,6) -> PAY-7014 | J19: 675 | K19: =WORKDAY(Table3[[#This Row],[Date of invoice]],2) -> 46297 | L19: =IF(PR!$J19=0,PR!$G19*50%,PR!$J19) -> 675 | M19: =IF(L19=G19,"Paid All",G19-L19) -> -50 | N19: =ARD!L25 -> 675
C20: =C19+1 -> 15 | D20: =IR!A16 -> INV-2026-015 | E20: =VLOOKUP(PR!$D20,IR!$A$2:$F$101,2) -> Oscar Baker | F20: =VLOOKUP(PR!$D20,IR!$A$2:$F$101,3) -> 46175 | G20: =VLOOKUP(PR!$D20,IR!$A$2:$F$101,4) -> 1120.8 | H20: =VLOOKUP(PR!$D20,IR!$A$2:$F$101,5) -> Project delivery | I20: =VLOOKUP(PR!$D20,IR!$A$2:$F$101,6) -> PAY-7015 | K20: =WORKDAY(Table3[[#This Row],[Date of invoice]],2) -> 46177 | L20: =IF(PR!$J20=0,PR!$G20*50%,PR!$J20) -> 560.4 | M20: =IF(L20=G20,"Paid All",G20-L20) -> 560.4 | N20: =ARD!L26 -> 773.352
C21: =C20+1 -> 16 | D21: =IR!A17 -> INV-2026-016 | E21: =VLOOKUP(PR!$D21,IR!$A$2:$F$101,2) -> Emily Adams | F21: =VLOOKUP(PR!$D21,IR!$A$2:$F$101,3) -> 46299 | G21: =VLOOKUP(PR!$D21,IR!$A$2:$F$101,4) -> 890 | H21: =VLOOKUP(PR!$D21,IR!$A$2:$F$101,5) -> Marketing services | I21: =VLOOKUP(PR!$D21,IR!$A$2:$F$101,6) -> PAY-7016 | K21: =WORKDAY(Table3[[#This Row],[Date of invoice]],2) -> 46301 | L21: =IF(PR!$J21=0,PR!$G21*50%,PR!$J21) -> 445 | M21: =IF(L21=G21,"Paid All",G21-L21) -> 445 | N21: =ARD!L27 -> 445
C22: =C21+1 -> 17 | D22: =IR!A18 -> INV-2026-017 | E22: =VLOOKUP(PR!$D22,IR!$A$2:$F$101,2) -> William Nelson | F22: =VLOOKUP(PR!$D22,IR!$A$2:$F$101,3) -> 46301 | G22: =VLOOKUP(PR!$D22,IR!$A$2:$F$101,4) -> 410.5 | H22: =VLOOKUP(PR!$D22,IR!$A$2:$F$101,5) -> Maintenance services | I22: =VLOOKUP(PR!$D22,IR!$A$2:$F$101,6) -> PAY-7017 | K22: =WORKDAY(Table3[[#This Row],[Date of invoice]],2) -> 46303 | L22: =IF(PR!$J22=0,PR!$G22*50%,PR!$J22) -> 205.25 | M22: =IF(L22=G22,"Paid All",G22-L22) -> 205.25 | N22: =ARD!L28 -> 205.25
C23: =C22+1 -> 18 | D23: =IR!A19 -> INV-2026-018 | E23: =VLOOKUP(PR!$D23,IR!$A$2:$F$101,2) -> Ella Hill | F23: =VLOOKUP(PR!$D23,IR!$A$2:$F$101,3) -> 46303 | G23: =VLOOKUP(PR!$D23,IR!$A$2:$F$101,4) -> 1675 | H23: =VLOOKUP(PR!$D23,IR!$A$2:$F$101,5) -> Software licence | I23: =VLOOKUP(PR!$D23,IR!$A$2:$F$101,6) -> PAY-7018 | J23: 1675 | K23: =WORKDAY(Table3[[#This Row],[Date of invoice]],2) -> 46307 | L23: =IF(PR!$J23=0,PR!$G23*50%,PR!$J23) -> 1675 | M23: =IF(L23=G23,"Paid All",G23-L23) -> Paid All | N23: =ARD!L29 -> 1675
C24: =C23+1 -> 19 | D24: =IR!A20 -> INV-2026-019 | E24: =VLOOKUP(PR!$D24,IR!$A$2:$F$101,2) -> James Lewis | F24: =VLOOKUP(PR!$D24,IR!$A$2:$F$101,3) -> 46305 | G24: =VLOOKUP(PR!$D24,IR!$A$2:$F$101,4) -> 295 | H24: =VLOOKUP(PR!$D24,IR!$A$2:$F$101,5) -> Stationery order | I24: =VLOOKUP(PR!$D24,IR!$A$2:$F$101,6) -> PAY-7019 | K24: =WORKDAY(Table3[[#This Row],[Date of invoice]],2) -> 46308 | L24: =IF(PR!$J24=0,PR!$G24*50%,PR!$J24) -> 147.5 | M24: =IF(L24=G24,"Paid All",G24-L24) -> 147.5 | N24: =ARD!L30 -> 147.5
C25: =C24+1 -> 20 | D25: =IR!A21 -> INV-2026-020 | E25: =VLOOKUP(PR!$D25,IR!$A$2:$F$101,2) -> Freya Clark | F25: =VLOOKUP(PR!$D25,IR!$A$2:$F$101,3) -> 46307 | G25: =VLOOKUP(PR!$D25,IR!$A$2:$F$101,4) -> 1350.25 | H25: =VLOOKUP(PR!$D25,IR!$A$2:$F$101,5) -> Training services | I25: =VLOOKUP(PR!$D25,IR!$A$2:$F$101,6) -> PAY-7020 | K25: =WORKDAY(Table3[[#This Row],[Date of invoice]],2) -> 46309 | L25: =IF(PR!$J25=0,PR!$G25*50%,PR!$J25) -> 675.125 | M25: =IF(L25=G25,"Paid All",G25-L25) -> 675.125 | N25: =ARD!L31 -> 675.125
C26: =C25+1 -> 21 | D26: =IR!A22 -> INV-2026-021 | E26: =VLOOKUP(PR!$D26,IR!$A$2:$F$101,2) -> Henry Lewis | F26: =VLOOKUP(PR!$D26,IR!$A$2:$F$101,3) -> 46309 | G26: =VLOOKUP(PR!$D26,IR!$A$2:$F$101,4) -> 725 | H26: =VLOOKUP(PR!$D26,IR!$A$2:$F$101,5) -> Office supplies | I26: =VLOOKUP(PR!$D26,IR!$A$2:$F$101,6) -> PAY-7021 | J26: 725 | K26: =WORKDAY(Table3[[#This Row],[Date of invoice]],2) -> 46311 | L26: =IF(PR!$J26=0,PR!$G26*50%,PR!$J26) -> 725 | M26: =IF(L26=G26,"Paid All",G26-L26) -> Paid All | N26: =ARD!L32 -> 725
C27: =C26+1 -> 22 | D27: =IR!A23 -> INV-2026-022 | E27: =VLOOKUP(PR!$D27,IR!$A$2:$F$101,2) -> Poppy Robinson | F27: =VLOOKUP(PR!$D27,IR!$A$2:$F$101,3) -> 46311 | G27: =VLOOKUP(PR!$D27,IR!$A$2:$F$101,4) -> 2350.5 | H27: =VLOOKUP(PR!$D27,IR!$A$2:$F$101,5) -> Consulting services | I27: =VLOOKUP(PR!$D27,IR!$A$2:$F$101,6) -> PAY-7022 | K27: =WORKDAY(Table3[[#This Row],[Date of invoice]],2) -> 46315 | L27: =IF(PR!$J27=0,PR!$G27*50%,PR!$J27) -> 1175.25 | M27: =IF(L27=G27,"Paid All",G27-L27) -> 1175.25 | N27: =ARD!L33 -> 1175.25
C28: =C27+1 -> 23 | D28: =IR!A24 -> INV-2026-023 | E28: =VLOOKUP(PR!$D28,IR!$A$2:$F$101,2) -> Alfie Walker | F28: =VLOOKUP(PR!$D28,IR!$A$2:$F$101,3) -> 46252 | G28: =VLOOKUP(PR!$D28,IR!$A$2:$F$101,4) -> 560 | H28: =VLOOKUP(PR!$D28,IR!$A$2:$F$101,5) -> Equipment purchase | I28: =VLOOKUP(PR!$D28,IR!$A$2:$F$101,6) -> PAY-7023 | J28: 580 | K28: =WORKDAY(Table3[[#This Row],[Date of invoice]],2) -> 46254 | L28: =IF(PR!$J28=0,PR!$G28*50%,PR!$J28) -> 580 | M28: =IF(L28=G28,"Paid All",G28-L28) -> -20 | N28: =ARD!L34 -> 580
C29: =C28+1 -> 24 | D29: =IR!A25 -> INV-2026-024 | E29: =VLOOKUP(PR!$D29,IR!$A$2:$F$101,2) -> Evie Hall | F29: =VLOOKUP(PR!$D29,IR!$A$2:$F$101,3) -> 46256 | G29: =VLOOKUP(PR!$D29,IR!$A$2:$F$101,4) -> 1025.75 | H29: =VLOOKUP(PR!$D29,IR!$A$2:$F$101,5) -> Monthly subscription | I29: =VLOOKUP(PR!$D29,IR!$A$2:$F$101,6) -> PAY-7024 | K29: =WORKDAY(Table3[[#This Row],[Date of invoice]],2) -> 46259 | L29: =IF(PR!$J29=0,PR!$G29*50%,PR!$J29) -> 512.875 | M29: =IF(L29=G29,"Paid All",G29-L29) -> 512.875 | N29: =ARD!L35 -> 584.6775
C30: =C29+1 -> 25 | D30: =IR!A26 -> INV-2026-025 | E30: =VLOOKUP(PR!$D30,IR!$A$2:$F$101,2) -> Leo Young | F30: =VLOOKUP(PR!$D30,IR!$A$2:$F$101,3) -> 46262 | G30: =VLOOKUP(PR!$D30,IR!$A$2:$F$101,4) -> 440 | H30: =VLOOKUP(PR!$D30,IR!$A$2:$F$101,5) -> Project delivery | I30: =VLOOKUP(PR!$D30,IR!$A$2:$F$101,6) -> PAY-7025 | K30: =WORKDAY(Table3[[#This Row],[Date of invoice]],2) -> 46266 | L30: =IF(PR!$J30=0,PR!$G30*50%,PR!$J30) -> 220 | M30: =IF(L30=G30,"Paid All",G30-L30) -> 220 | N30: =ARD!L36 -> 244.2
C31: =C30+1 -> 26 | D31: =IR!A27 -> INV-2026-026 | E31: =VLOOKUP(PR!$D31,IR!$A$2:$F$101,2) -> Florence King | F31: =VLOOKUP(PR!$D31,IR!$A$2:$F$101,3) -> 46268 | G31: =VLOOKUP(PR!$D31,IR!$A$2:$F$101,4) -> 1780 | H31: =VLOOKUP(PR!$D31,IR!$A$2:$F$101,5) -> Marketing services | I31: =VLOOKUP(PR!$D31,IR!$A$2:$F$101,6) -> PAY-7026 | K31: =WORKDAY(Table3[[#This Row],[Date of invoice]],2) -> 46272 | L31: =IF(PR!$J31=0,PR!$G31*50%,PR!$J31) -> 890 | M31: =IF(L31=G31,"Paid All",G31-L31) -> 890 | N31: =ARD!L37 -> 961.2
C32: =C31+1 -> 27 | D32: =IR!A28 -> INV-2026-027 | E32: =VLOOKUP(PR!$D32,IR!$A$2:$F$101,2) -> Archie Wright | F32: =VLOOKUP(PR!$D32,IR!$A$2:$F$101,3) -> 46272 | G32: =VLOOKUP(PR!$D32,IR!$A$2:$F$101,4) -> 315.25 | H32: =VLOOKUP(PR!$D32,IR!$A$2:$F$101,5) -> Maintenance services | I32: =VLOOKUP(PR!$D32,IR!$A$2:$F$101,6) -> PAY-7027 | K32: =WORKDAY(Table3[[#This Row],[Date of invoice]],2) -> 46274 | L32: =IF(PR!$J32=0,PR!$G32*50%,PR!$J32) -> 157.625 | M32: =IF(L32=G32,"Paid All",G32-L32) -> 157.625 | N32: =ARD!L38 -> 165.50625
C33: =C32+1 -> 28 | D33: =IR!A29 -> INV-2026-028 | E33: =VLOOKUP(PR!$D33,IR!$A$2:$F$101,2) -> Ivy Scott | F33: =VLOOKUP(PR!$D33,IR!$A$2:$F$101,3) -> 46276 | G33: =VLOOKUP(PR!$D33,IR!$A$2:$F$101,4) -> 940 | H33: =VLOOKUP(PR!$D33,IR!$A$2:$F$101,5) -> Software licence | I33: =VLOOKUP(PR!$D33,IR!$A$2:$F$101,6) -> PAY-7028 | K33: =WORKDAY(Table3[[#This Row],[Date of invoice]],2) -> 46280 | L33: =IF(PR!$J33=0,PR!$G33*50%,PR!$J33) -> 470 | M33: =IF(L33=G33,"Paid All",G33-L33) -> 470 | N33: =ARD!L39 -> 479.4
C34: =C33+1 -> 29 | D34: =IR!A30 -> INV-2026-029 | E34: =VLOOKUP(PR!$D34,IR!$A$2:$F$101,2) -> Freddie Green | F34: =VLOOKUP(PR!$D34,IR!$A$2:$F$101,3) -> 46279 | G34: =VLOOKUP(PR!$D34,IR!$A$2:$F$101,4) -> 2450 | H34: =VLOOKUP(PR!$D34,IR!$A$2:$F$101,5) -> Stationery order | I34: =VLOOKUP(PR!$D34,IR!$A$2:$F$101,6) -> PAY-7029 | K34: =WORKDAY(Table3[[#This Row],[Date of invoice]],2) -> 46281 | L34: =IF(PR!$J34=0,PR!$G34*50%,PR!$J34) -> 1225 | M34: =IF(L34=G34,"Paid All",G34-L34) -> 1225 | N34: =ARD!L40 -> 1249.5
C35: =C34+1 -> 30 | D35: =IR!A31 -> INV-2026-030 | E35: =VLOOKUP(PR!$D35,IR!$A$2:$F$101,2) -> Elsie Baker | F35: =VLOOKUP(PR!$D35,IR!$A$2:$F$101,3) -> 46282 | G35: =VLOOKUP(PR!$D35,IR!$A$2:$F$101,4) -> 685.5 | H35: =VLOOKUP(PR!$D35,IR!$A$2:$F$101,5) -> Training services | I35: =VLOOKUP(PR!$D35,IR!$A$2:$F$101,6) -> PAY-7030 | J35: 685 | K35: =WORKDAY(Table3[[#This Row],[Date of invoice]],2) -> 46286 | L35: =IF(PR!$J35=0,PR!$G35*50%,PR!$J35) -> 685 | M35: =IF(L35=G35,"Paid All",G35-L35) -> 0.5 | N35: =ARD!L41 -> 685
C36: =C35+1 -> 31 | D36: =IR!A32 -> INV-2026-031 | E36: =VLOOKUP(PR!$D36,IR!$A$2:$F$101,2) -> Ethan Adams | F36: =VLOOKUP(PR!$D36,IR!$A$2:$F$101,3) -> 46286 | G36: =VLOOKUP(PR!$D36,IR!$A$2:$F$101,4) -> 1150 | H36: =VLOOKUP(PR!$D36,IR!$A$2:$F$101,5) -> Office supplies | I36: =VLOOKUP(PR!$D36,IR!$A$2:$F$101,6) -> PAY-7031 | K36: =WORKDAY(Table3[[#This Row],[Date of invoice]],2) -> 46288 | L36: =IF(PR!$J36=0,PR!$G36*50%,PR!$J36) -> 575 | M36: =IF(L36=G36,"Paid All",G36-L36) -> 575 | N36: =ARD!L42 -> 575
C37: =C36+1 -> 32 | D37: =IR!A33 -> INV-2026-032 | E37: =VLOOKUP(PR!$D37,IR!$A$2:$F$101,2) -> Ruby Nelson | F37: =VLOOKUP(PR!$D37,IR!$A$2:$F$101,3) -> 46289 | G37: =VLOOKUP(PR!$D37,IR!$A$2:$F$101,4) -> 395.75 | H37: =VLOOKUP(PR!$D37,IR!$A$2:$F$101,5) -> Consulting services | I37: =VLOOKUP(PR!$D37,IR!$A$2:$F$101,6) -> PAY-7032 | K37: =WORKDAY(Table3[[#This Row],[Date of invoice]],2) -> 46293 | L37: =IF(PR!$J37=0,PR!$G37*50%,PR!$J37) -> 197.875 | M37: =IF(L37=G37,"Paid All",G37-L37) -> 197.875 | N37: =ARD!L43 -> 197.875
C38: =C37+1 -> 33 | D38: =IR!A34 -> INV-2026-033 | E38: =VLOOKUP(PR!$D38,IR!$A$2:$F$101,2) -> Lucas Hill | F38: =VLOOKUP(PR!$D38,IR!$A$2:$F$101,3) -> 46292 | G38: =VLOOKUP(PR!$D38,IR!$A$2:$F$101,4) -> 2850 | H38: =VLOOKUP(PR!$D38,IR!$A$2:$F$101,5) -> Equipment purchase | I38: =VLOOKUP(PR!$D38,IR!$A$2:$F$101,6) -> PAY-7033 | K38: =WORKDAY(Table3[[#This Row],[Date of invoice]],2) -> 46294 | L38: =IF(PR!$J38=0,PR!$G38*50%,PR!$J38) -> 1425 | M38: =IF(L38=G38,"Paid All",G38-L38) -> 1425 | N38: =ARD!L44 -> 1425
C39: =C38+1 -> 34 | D39: =IR!A35 -> INV-2026-034 | E39: =VLOOKUP(PR!$D39,IR!$A$2:$F$101,2) -> Daisy Lewis | F39: =VLOOKUP(PR!$D39,IR!$A$2:$F$101,3) -> 46294 | G39: =VLOOKUP(PR!$D39,IR!$A$2:$F$101,4) -> 760 | H39: =VLOOKUP(PR!$D39,IR!$A$2:$F$101,5) -> Monthly subscription | I39: =VLOOKUP(PR!$D39,IR!$A$2:$F$101,6) -> PAY-7034 | K39: =WORKDAY(Table3[[#This Row],[Date of invoice]],2) -> 46296 | L39: =IF(PR!$J39=0,PR!$G39*50%,PR!$J39) -> 380 | M39: =IF(L39=G39,"Paid All",G39-L39) -> 380 | N39: =ARD!L45 -> 380
C40: =C39+1 -> 35 | D40: =IR!A36 -> INV-2026-035 | E40: =VLOOKUP(PR!$D40,IR!$A$2:$F$101,2) -> Finley Clark | F40: =VLOOKUP(PR!$D40,IR!$A$2:$F$101,3) -> 46296 | G40: =VLOOKUP(PR!$D40,IR!$A$2:$F$101,4) -> 1425.5 | H40: =VLOOKUP(PR!$D40,IR!$A$2:$F$101,5) -> Project delivery | I40: =VLOOKUP(PR!$D40,IR!$A$2:$F$101,6) -> PAY-7035 | K40: =WORKDAY(Table3[[#This Row],[Date of invoice]],2) -> 46300 | L40: =IF(PR!$J40=0,PR!$G40*50%,PR!$J40) -> 712.75 | M40: =IF(L40=G40,"Paid All",G40-L40) -> 712.75 | N40: =ARD!L46 -> 712.75
C41: =C40+1 -> 36 | D41: =IR!A37 -> INV-2026-036 | E41: =VLOOKUP(PR!$D41,IR!$A$2:$F$101,2) -> Chloe Mitchell | F41: =VLOOKUP(PR!$D41,IR!$A$2:$F$101,3) -> 46298 | G41: =VLOOKUP(PR!$D41,IR!$A$2:$F$101,4) -> 530 | H41: =VLOOKUP(PR!$D41,IR!$A$2:$F$101,5) -> Marketing services | I41: =VLOOKUP(PR!$D41,IR!$A$2:$F$101,6) -> PAY-7036 | J41: 560 | K41: =WORKDAY(Table3[[#This Row],[Date of invoice]],2) -> 46301 | L41: =IF(PR!$J41=0,PR!$G41*50%,PR!$J41) -> 560 | M41: =IF(L41=G41,"Paid All",G41-L41) -> -30 | N41: =ARD!L47 -> 560
C42: =C41+1 -> 37 | D42: =IR!A38 -> INV-2026-037 | E42: =VLOOKUP(PR!$D42,IR!$A$2:$F$101,2) -> Mason Thompson | F42: =VLOOKUP(PR!$D42,IR!$A$2:$F$101,3) -> 46300 | G42: =VLOOKUP(PR!$D42,IR!$A$2:$F$101,4) -> 975.25 | H42: =VLOOKUP(PR!$D42,IR!$A$2:$F$101,5) -> Maintenance services | I42: =VLOOKUP(PR!$D42,IR!$A$2:$F$101,6) -> PAY-7037 | K42: =WORKDAY(Table3[[#This Row],[Date of invoice]],2) -> 46302 | L42: =IF(PR!$J42=0,PR!$G42*50%,PR!$J42) -> 487.625 | M42: =IF(L42=G42,"Paid All",G42-L42) -> 487.625 | N42: =ARD!L48 -> 487.625
C43: =C42+1 -> 38 | D43: =IR!A39 -> INV-2026-038 | E43: =VLOOKUP(PR!$D43,IR!$A$2:$F$101,2) -> Sophie Wilson | F43: =VLOOKUP(PR!$D43,IR!$A$2:$F$101,3) -> 46302 | G43: =VLOOKUP(PR!$D43,IR!$A$2:$F$101,4) -> 1850 | H43: =VLOOKUP(PR!$D43,IR!$A$2:$F$101,5) -> Software licence | I43: =VLOOKUP(PR!$D43,IR!$A$2:$F$101,6) -> PAY-7038 | K43: =WORKDAY(Table3[[#This Row],[Date of invoice]],2) -> 46304 | L43: =IF(PR!$J43=0,PR!$G43*50%,PR!$J43) -> 925 | M43: =IF(L43=G43,"Paid All",G43-L43) -> 925 | N43: =ARD!L49 -> 925
...

Sheet CT
B2: CREDIT TRACKER
B4: S.NO | C4: Invoice Number | D4: Customer Name | E4: Date of invoice | F4: Invoice Amount | G4: Payment Note | H4: Payment Refence | I4: Date of Deposit | J4: Deposit Amount | K4: Outstanding Amount | L4: Amounts Paid | M4: Credit Terms (Days)
B5: 1 | C5: =IR!A2 -> INV-2026-001 | D5: =VLOOKUP(Table4[[#This Row],[Invoice Number]],PR!$D$6:$I$110,2) -> Oliver Bennett | E5: =VLOOKUP(Table4[[#This Row],[Invoice Number]],PR!$D$6:$I$110,3) -> 46311 | F5: =VLOOKUP(Table4[[#This Row],[Invoice Number]],PR!$D$6:$I$110,4) -> 450 | G5: =VLOOKUP(Table4[[#This Row],[Invoice Number]],PR!$D$6:$I$110,5) -> Office supplies | H5: =VLOOKUP(Table4[[#This Row],[Invoice Number]],PR!$D$6:$I$110,6) -> PAY-7001 | J5: =VLOOKUP(Table4[[#This Row],[Invoice Number]],PR!$D$6:$M$110,9) -> 225 | K5: =VLOOKUP(Table4[[#This Row],[Invoice Number]],PR!$D$6:$M$110,10) -> 225 | L5: =PR!N6 -> 225 | M5: 30
B6: =B5+1 -> 2 | C6: =IR!A3 -> INV-2026-002 | D6: =VLOOKUP(Table4[[#This Row],[Invoice Number]],PR!$D$6:$I$110,2) -> Amelia Carter | E6: =VLOOKUP(Table4[[#This Row],[Invoice Number]],PR!$D$6:$I$110,3) -> 46254 | F6: =VLOOKUP(Table4[[#This Row],[Invoice Number]],PR!$D$6:$I$110,4) -> 1250.5 | G6: =VLOOKUP(Table4[[#This Row],[Invoice Number]],PR!$D$6:$I$110,5) -> Consulting services | H6: =VLOOKUP(Table4[[#This Row],[Invoice Number]],PR!$D$6:$I$110,6) -> PAY-7002 | J6: =VLOOKUP(Table4[[#This Row],[Invoice Number]],PR!$D$6:$M$110,9) -> 625.25 | K6: =VLOOKUP(Table4[[#This Row],[Invoice Number]],PR!$D$6:$M$110,10) -> 625.25 | L6: =PR!N7 -> 731.5425 | M6: 30
B7: =B6+1 -> 3 | C7: =IR!A4 -> INV-2026-003 | D7: =VLOOKUP(Table4[[#This Row],[Invoice Number]],PR!$D$6:$I$110,2) -> George Mitchell | E7: =VLOOKUP(Table4[[#This Row],[Invoice Number]],PR!$D$6:$I$110,3) -> 46259 | F7: =VLOOKUP(Table4[[#This Row],[Invoice Number]],PR!$D$6:$I$110,4) -> 785.25 | G7: =VLOOKUP(Table4[[#This Row],[Invoice Number]],PR!$D$6:$I$110,5) -> Equipment purchase | H7: =VLOOKUP(Table4[[#This Row],[Invoice Number]],PR!$D$6:$I$110,6) -> PAY-7003 | J7: =VLOOKUP(Table4[[#This Row],[Invoice Number]],PR!$D$6:$M$110,9) -> 785.25 | K7: =VLOOKUP(Table4[[#This Row],[Invoice Number]],PR!$D$6:$M$110,10) -> Paid All | L7: =PR!N8 -> 785.25 | M7: 30
B8: =B7+1 -> 4 | C8: =IR!A5 -> INV-2026-004 | D8: =VLOOKUP(Table4[[#This Row],[Invoice Number]],PR!$D$6:$I$110,2) -> Isla Thompson | E8: =VLOOKUP(Table4[[#This Row],[Invoice Number]],PR!$D$6:$I$110,3) -> 46267 | F8: =VLOOKUP(Table4[[#This Row],[Invoice Number]],PR!$D$6:$I$110,4) -> 320 | G8: =VLOOKUP(Table4[[#This Row],[Invoice Number]],PR!$D$6:$I$110,5) -> Monthly subscription | H8: =VLOOKUP(Table4[[#This Row],[Invoice Number]],PR!$D$6:$I$110,6) -> PAY-7004 | J8: =VLOOKUP(Table4[[#This Row],[Invoice Number]],PR!$D$6:$M$110,9) -> 160 | K8: =VLOOKUP(Table4[[#This Row],[Invoice Number]],PR!$D$6:$M$110,10) -> 160 | L8: =PR!N9 -> 172.8 | M8: 30
B9: =B8+1 -> 5 | C9: =IR!A6 -> INV-2026-005 | D9: =VLOOKUP(Table4[[#This Row],[Invoice Number]],PR!$D$6:$I$110,2) -> Harry Wilson | E9: =VLOOKUP(Table4[[#This Row],[Invoice Number]],PR!$D$6:$I$110,3) -> 46270 | F9: =VLOOKUP(Table4[[#This Row],[Invoice Number]],PR!$D$6:$I$110,4) -> 2100 | G9: =VLOOKUP(Table4[[#This Row],[Invoice Number]],PR!$D$6:$I$110,5) -> Project delivery | H9: =VLOOKUP(Table4[[#This Row],[Invoice Number]],PR!$D$6:$I$110,6) -> PAY-7005 | J9: =VLOOKUP(Table4[[#This Row],[Invoice Number]],PR!$D$6:$M$110,9) -> 1050 | K9: =VLOOKUP(Table4[[#This Row],[Invoice Number]],PR!$D$6:$M$110,10) -> 1050 | L9: =PR!N10 -> 1134 | M9: 30
B10: =B9+1 -> 6 | C10: =IR!A7 -> INV-2026-006 | D10: =VLOOKUP(Table4[[#This Row],[Invoice Number]],PR!$D$6:$I$110,2) -> Ava Robinson | E10: =VLOOKUP(Table4[[#This Row],[Invoice Number]],PR!$D$6:$I$110,3) -> 46275 | F10: =VLOOKUP(Table4[[#This Row],[Invoice Number]],PR!$D$6:$I$110,4) -> 675.8 | G10: =VLOOKUP(Table4[[#This Row],[Invoice Number]],PR!$D$6:$I$110,5) -> Marketing services | H10: =VLOOKUP(Table4[[#This Row],[Invoice Number]],PR!$D$6:$I$110,6) -> PAY-7006 | J10: =VLOOKUP(Table4[[#This Row],[Invoice Number]],PR!$D$6:$M$110,9) -> 337.9 | K10: =VLOOKUP(Table4[[#This Row],[Invoice Number]],PR!$D$6:$M$110,10) -> 337.9 | L10: =PR!N11 -> 354.795 | M10: 30
B11: =B10+1 -> 7 | C11: =IR!A8 -> INV-2026-007 | D11: =VLOOKUP(Table4[[#This Row],[Invoice Number]],PR!$D$6:$I$110,2) -> Noah Walker | E11: =VLOOKUP(Table4[[#This Row],[Invoice Number]],PR!$D$6:$I$110,3) -> 46277 | F11: =VLOOKUP(Table4[[#This Row],[Invoice Number]],PR!$D$6:$I$110,4) -> 540 | G11: =VLOOKUP(Table4[[#This Row],[Invoice Number]],PR!$D$6:$I$110,5) -> Maintenance services | H11: =VLOOKUP(Table4[[#This Row],[Invoice Number]],PR!$D$6:$I$110,6) -> PAY-7007 | J11: =VLOOKUP(Table4[[#This Row],[Invoice Number]],PR!$D$6:$M$110,9) -> 540 | K11: =VLOOKUP(Table4[[#This Row],[Invoice Number]],PR!$D$6:$M$110,10) -> Paid All | L11: =PR!N12 -> 540 | M11: 30
B12: =B11+1 -> 8 | C12: =IR!A9 -> INV-2026-008 | D12: =VLOOKUP(Table4[[#This Row],[Invoice Number]],PR!$D$6:$I$110,2) -> Grace Hall | E12: =VLOOKUP(Table4[[#This Row],[Invoice Number]],PR!$D$6:$I$110,3) -> 46280 | F12: =VLOOKUP(Table4[[#This Row],[Invoice Number]],PR!$D$6:$I$110,4) -> 1890.75 | G12: =VLOOKUP(Table4[[#This Row],[Invoice Number]],PR!$D$6:$I$110,5) -> Software licence | H12: =VLOOKUP(Table4[[#This Row],[Invoice Number]],PR!$D$6:$I$110,6) -> PAY-7008 | J12: =VLOOKUP(Table4[[#This Row],[Invoice Number]],PR!$D$6:$M$110,9) -> 945.375 | K12: =VLOOKUP(Table4[[#This Row],[Invoice Number]],PR!$D$6:$M$110,10) -> 945.375 | L12: =PR!N13 -> 964.2825 | M12: 30
B13: =B12+1 -> 9 | C13: =IR!A10 -> INV-2026-009 | D13: =VLOOKUP(Table4[[#This Row],[Invoice Number]],PR!$D$6:$I$110,2) -> Jack Young | E13: =VLOOKUP(Table4[[#This Row],[Invoice Number]],PR!$D$6:$I$110,3) -> 46283 | F13: =VLOOKUP(Table4[[#This Row],[Invoice Number]],PR!$D$6:$I$110,4) -> 265.5 | G13: =VLOOKUP(Table4[[#This Row],[Invoice Number]],PR!$D$6:$I$110,5) -> Stationery order | H13: =VLOOKUP(Table4[[#This Row],[Invoice Number]],PR!$D$6:$I$110,6) -> PAY-7009 | J13: =VLOOKUP(Table4[[#This Row],[Invoice Number]],PR!$D$6:$M$110,9) -> 265.5 | K13: =VLOOKUP(Table4[[#This Row],[Invoice Number]],PR!$D$6:$M$110,10) -> Paid All | L13: =PR!N14 -> 265.5 | M13: 30
B14: =B13+1 -> 10 | C14: =IR!A11 -> INV-2026-010 | D14: =VLOOKUP(Table4[[#This Row],[Invoice Number]],PR!$D$6:$I$110,2) -> Lily Allen | E14: =VLOOKUP(Table4[[#This Row],[Invoice Number]],PR!$D$6:$I$110,3) -> 46285 | F14: =VLOOKUP(Table4[[#This Row],[Invoice Number]],PR!$D$6:$I$110,4) -> 980 | G14: =VLOOKUP(Table4[[#This Row],[Invoice Number]],PR!$D$6:$I$110,5) -> Training services | H14: =VLOOKUP(Table4[[#This Row],[Invoice Number]],PR!$D$6:$I$110,6) -> PAY-7010 | J14: =VLOOKUP(Table4[[#This Row],[Invoice Number]],PR!$D$6:$M$110,9) -> 490 | K14: =VLOOKUP(Table4[[#This Row],[Invoice Number]],PR!$D$6:$M$110,10) -> 490 | L14: =PR!N15 -> 490 | M14: 30
B15: =B14+1 -> 11 | C15: =IR!A12 -> INV-2026-011 | D15: =VLOOKUP(Table4[[#This Row],[Invoice Number]],PR!$D$6:$I$110,2) -> Charlie King | E15: =VLOOKUP(Table4[[#This Row],[Invoice Number]],PR!$D$6:$I$110,3) -> 46287 | F15: =VLOOKUP(Table4[[#This Row],[Invoice Number]],PR!$D$6:$I$110,4) -> 1450 | G15: =VLOOKUP(Table4[[#This Row],[Invoice Number]],PR!$D$6:$I$110,5) -> Consulting services | H15: =VLOOKUP(Table4[[#This Row],[Invoice Number]],PR!$D$6:$I$110,6) -> PAY-7011 | J15: =VLOOKUP(Table4[[#This Row],[Invoice Number]],PR!$D$6:$M$110,9) -> 725 | K15: =VLOOKUP(Table4[[#This Row],[Invoice Number]],PR!$D$6:$M$110,10) -> 725 | L15: =PR!N16 -> 725 | M15: 30
B16: =B15+1 -> 12 | C16: =IR!A13 -> INV-2026-012 | D16: =VLOOKUP(Table4[[#This Row],[Invoice Number]],PR!$D$6:$I$110,2) -> Mia Wright | E16: =VLOOKUP(Table4[[#This Row],[Invoice Number]],PR!$D$6:$I$110,3) -> 46290 | F16: =VLOOKUP(Table4[[#This Row],[Invoice Number]],PR!$D$6:$I$110,4) -> 375.25 | G16: =VLOOKUP(Table4[[#This Row],[Invoice Number]],PR!$D$6:$I$110,5) -> Office supplies | H16: =VLOOKUP(Table4[[#This Row],[Invoice Number]],PR!$D$6:$I$110,6) -> PAY-7012 | J16: =VLOOKUP(Table4[[#This Row],[Invoice Number]],PR!$D$6:$M$110,9) -> 187.625 | K16: =VLOOKUP(Table4[[#This Row],[Invoice Number]],PR!$D$6:$M$110,10) -> 187.625 | L16: =PR!N17 -> 187.625 | M16: 30
B17: =B16+1 -> 13 | C17: =IR!A14 -> INV-2026-013 | D17: =VLOOKUP(Table4[[#This Row],[Invoice Number]],PR!$D$6:$I$110,2) -> Thomas Scott | E17: =VLOOKUP(Table4[[#This Row],[Invoice Number]],PR!$D$6:$I$110,3) -> 46293 | F17: =VLOOKUP(Table4[[#This Row],[Invoice Number]],PR!$D$6:$I$110,4) -> 2750 | G17: =VLOOKUP(Table4[[#This Row],[Invoice Number]],PR!$D$6:$I$110,5) -> Equipment purchase | H17: =VLOOKUP(Table4[[#This Row],[Invoice Number]],PR!$D$6:$I$110,6) -> PAY-7013 | J17: =VLOOKUP(Table4[[#This Row],[Invoice Number]],PR!$D$6:$M$110,9) -> 1375 | K17: =VLOOKUP(Table4[[#This Row],[Invoice Number]],PR!$D$6:$M$110,10) -> 1375 | L17: =PR!N18 -> 1375 | M17: 30
... B104: =B103+1 -> 100 | C104: =IR!A101 -> INV-2026-100 | D104: =VLOOKUP(Table4[[#This Row],[Invoice Number]],PR!$D$6:$I$110,2) -> Victoria Taylor | E104: =VLOOKUP(Table4[[#This Row],[Invoice Number]],PR!$D$6:$I$110,3) -> 46253 | F104: =VLOOKUP(Table4[[#This Row],[Invoice Number]],PR!$D$6:$I$110,4) -> 1285 | G104: =VLOOKUP(Table4[[#This Row],[Invoice Number]],PR!$D$6:$I$110,5) -> Training services | H104: =VLOOKUP(Table4[[#This Row],[Invoice Number]],PR!$D$6:$I$110,6) -> PAY-7100 | J104: =VLOOKUP(Table4[[#This Row],[Invoice Number]],PR!$D$6:$M$110,9) -> 642.5 | K104: =VLOOKUP(Table4[[#This Row],[Invoice Number]],PR!$D$6:$M$110,10) -> 642.5 | L104: =PR!N105 -> 751.725 | M104: 30

Sheet ARD
B2: Accounts Recievable Tracker
Q7: Days | R7: % Charge
C8: Accounts Recievable Days | F8: =TODAY() -> 46315 | Q8: 2 | R8: 0.01
Q9: 5 | R9: 0.02
Q10: =Q9+5 -> 10 | R10: =R9+3% -> 0.05
C11: S.no | D11: Invoice Number | E11: Customer Name | F11: Date of invoice | G11: Invoice Amount | H11: Payment Note | I11: Payment Refence | J11: Deposit Amount | K11: Outstanding Amount | L11: Amounts Paid | M11: Days Of Credit | N11: Credit Terms | O11: Due Days | P11: Column1 | Q11: =Q10+5 -> 15 | R11: =R10+3% -> 0.08
C12: 1 | D12: =PR!D6 -> INV-2026-001 | E12: =VLOOKUP(Table2[[#This Row],[Invoice Number]],Table4[[Invoice Number]:[Payment Refence]],2) -> Oliver Bennett | F12: =VLOOKUP(Table2[[#This Row],[Invoice Number]],Table4[[Invoice Number]:[Payment Refence]],3) -> 46311 | G12: =VLOOKUP(Table2[[#This Row],[Invoice Number]],Table4[[Invoice Number]:[Payment Refence]],4) -> 450 | H12: =VLOOKUP(Table2[[#This Row],[Invoice Number]],Table4[[Invoice Number]:[Payment Refence]],5) -> Office supplies | I12: =VLOOKUP(Table2[[#This Row],[Invoice Number]],Table4[[Invoice Number]:[Payment Refence]],6) -> PAY-7001 | J12: =VLOOKUP(Table2[[#This Row],[Invoice Number]],PR!$D$6:$M$110,9) -> 225 | K12: =CT!K5 -> 225 | L12: =IF(OR(Table2[[#This Row],[Outstanding Amount]]="Paid All",Table2[[#This Row],[Outstanding Amount]]<1,Table2[[#This Row],[Due Days]]<1,Table2[[#This Row],[Due Days]]=1,Table2[[#This Row],[Due Days]]=""),Table2[[#This Row],[Deposit Amount]],VLOOKUP(Table2[[#This Row],[Due Days]],$Q$8:$R$21,2)*Table2[[#This Row],[Outstanding Amount]]+Table2[[#This Row],[Outstanding Amount]]) -> 225 | M12: =IF(Table2[[#This Row],[Outstanding Amount]]>1,$F$8-Table2[[#This Row],[Date of invoice]],"") -> 4 | N12: =CT!M5 -> 30 | O12: =IF(OR(Table2[[#This Row],[Days Of Credit]]="",Table2[[#This Row],[Days Of Credit]]=Table2[[#This Row],[Credit Terms]],Table2[[#This Row],[Days Of Credit]]<Table2[[#This Row],[Credit Terms]]),"",Table2[[#This Row],[Days Of Credit]]-Table2[[#This Row],[Credit Terms]]) | Q12: =Q11+5 -> 20 | R12: =R11+3% -> 0.11
C13: =C12+1 -> 2 | D13: =PR!D7 -> INV-2026-002 | E13: =VLOOKUP(Table2[[#This Row],[Invoice Number]],Table4[[Invoice Number]:[Payment Refence]],2) -> Amelia Carter | F13: =VLOOKUP(Table2[[#This Row],[Invoice Number]],Table4[[Invoice Number]:[Payment Refence]],3) -> 46254 | G13: =VLOOKUP(Table2[[#This Row],[Invoice Number]],Table4[[Invoice Number]:[Payment Refence]],4) -> 1250.5 | H13: =VLOOKUP(Table2[[#This Row],[Invoice Number]],Table4[[Invoice Number]:[Payment Refence]],5) -> Consulting services | I13: =VLOOKUP(Table2[[#This Row],[Invoice Number]],Table4[[Invoice Number]:[Payment Refence]],6) -> PAY-7002 | J13: =VLOOKUP(Table2[[#This Row],[Invoice Number]],PR!$D$6:$M$110,9) -> 625.25 | K13: =CT!K6 -> 625.25 | L13: =IF(OR(Table2[[#This Row],[Outstanding Amount]]="Paid All",Table2[[#This Row],[Outstanding Amount]]<1,Table2[[#This Row],[Due Days]]<1,Table2[[#This Row],[Due Days]]=1,Table2[[#This Row],[Due Days]]=""),Table2[[#This Row],[Deposit Amount]],VLOOKUP(Table2[[#This Row],[Due Days]],$Q$8:$R$21,2)*Table2[[#This Row],[Outstanding Amount]]+Table2[[#This Row],[Outstanding Amount]]) -> 731.5425 | M13: =IF(Table2[[#This Row],[Outstanding Amount]]>1,$F$8-Table2[[#This Row],[Date of invoice]],"") -> 61 | N13: =CT!M6 -> 30 | O13: =IF(OR(Table2[[#This Row],[Days Of Credit]]="",Table2[[#This Row],[Days Of Credit]]=Table2[[#This Row],[Credit Terms]],Table2[[#This Row],[Days Of Credit]]<Table2[[#This Row],[Credit Terms]]),"",Table2[[#This Row],[Days Of Credit]]-Table2[[#This Row],[Credit Terms]]) -> 31 | Q13: =Q12+5 -> 25 | R13: =R12+3% -> 0.14
C14: =C13+1 -> 3 | D14: =PR!D8 -> INV-2026-003 | E14: =VLOOKUP(Table2[[#This Row],[Invoice Number]],Table4[[Invoice Number]:[Payment Refence]],2) -> George Mitchell | F14: =VLOOKUP(Table2[[#This Row],[Invoice Number]],Table4[[Invoice Number]:[Payment Refence]],3) -> 46259 | G14: =VLOOKUP(Table2[[#This Row],[Invoice Number]],Table4[[Invoice Number]:[Payment Refence]],4) -> 785.25 | H14: =VLOOKUP(Table2[[#This Row],[Invoice Number]],Table4[[Invoice Number]:[Payment Refence]],5) -> Equipment purchase | I14: =VLOOKUP(Table2[[#This Row],[Invoice Number]],Table4[[Invoice Number]:[Payment Refence]],6) -> PAY-7003 | J14: =VLOOKUP(Table2[[#This Row],[Invoice Number]],PR!$D$6:$M$110,9) -> 785.25 | K14: =CT!K7 -> Paid All | L14: =IF(OR(Table2[[#This Row],[Outstanding Amount]]="Paid All",Table2[[#This Row],[Outstanding Amount]]<1,Table2[[#This Row],[Due Days]]<1,Table2[[#This Row],[Due Days]]=1,Table2[[#This Row],[Due Days]]=""),Table2[[#This Row],[Deposit Amount]],VLOOKUP(Table2[[#This Row],[Due Days]],$Q$8:$R$21,2)*Table2[[#This Row],[Outstanding Amount]]+Table2[[#This Row],[Outstanding Amount]]) -> 785.25 | M14: =IF(Table2[[#This Row],[Outstanding Amount]]>1,$F$8-Table2[[#This Row],[Date of invoice]],"") -> 56 | N14: =CT!M7 -> 30 | O14: =IF(OR(Table2[[#This Row],[Days Of Credit]]="",Table2[[#This Row],[Days Of Credit]]=Table2[[#This Row],[Credit Terms]],Table2[[#This Row],[Days Of Credit]]<Table2[[#This Row],[Credit Terms]]),"",Table2[[#This Row],[Days Of Credit]]-Table2[[#This Row],[Credit Terms]]) -> 26 | Q14: =Q13+5 -> 30 | R14: =R13+3% -> 0.17
C15: =C14+1 -> 4 | D15: =PR!D9 -> INV-2026-004 | E15: =VLOOKUP(Table2[[#This Row],[Invoice Number]],Table4[[Invoice Number]:[Payment Refence]],2) -> Isla Thompson | F15: =VLOOKUP(Table2[[#This Row],[Invoice Number]],Table4[[Invoice Number]:[Payment Refence]],3) -> 46267 | G15: =VLOOKUP(Table2[[#This Row],[Invoice Number]],Table4[[Invoice Number]:[Payment Refence]],4) -> 320 | H15: =VLOOKUP(Table2[[#This Row],[Invoice Number]],Table4[[Invoice Number]:[Payment Refence]],5) -> Monthly subscription | I15: =VLOOKUP(Table2[[#This Row],[Invoice Number]],Table4[[Invoice Number]:[Payment Refence]],6) -> PAY-7004 | J15: =VLOOKUP(Table2[[#This Row],[Invoice Number]],PR!$D$6:$M$110,9) -> 160 | K15: =CT!K8 -> 160 | L15: =IF(OR(Table2[[#This Row],[Outstanding Amount]]="Paid All",Table2[[#This Row],[Outstanding Amount]]<1,Table2[[#This Row],[Due Days]]<1,Table2[[#This Row],[Due Days]]=1,Table2[[#This Row],[Due Days]]=""),Table2[[#This Row],[Deposit Amount]],VLOOKUP(Table2[[#This Row],[Due Days]],$Q$8:$R$21,2)*Table2[[#This Row],[Outstanding Amount]]+Table2[[#This Row],[Outstanding Amount]]) -> 172.8 | M15: =IF(Table2[[#This Row],[Outstanding Amount]]>1,$F$8-Table2[[#This Row],[Date of invoice]],"") -> 48 | N15: =CT!M8 -> 30 | O15: =IF(OR(Table2[[#This Row],[Days Of Credit]]="",Table2[[#This Row],[Days Of Credit]]=Table2[[#This Row],[Credit Terms]],Table2[[#This Row],[Days Of Credit]]<Table2[[#This Row],[Credit Terms]]),"",Table2[[#This Row],[Days Of Credit]]-Table2[[#This Row],[Credit Terms]]) -> 18 | Q15: =Q14+5 -> 35 | R15: =R14+3% -> 0.2
C16: =C15+1 -> 5 | D16: =PR!D10 -> INV-2026-005 | E16: =VLOOKUP(Table2[[#This Row],[Invoice Number]],Table4[[Invoice Number]:[Payment Refence]],2) -> Harry Wilson | F16: =VLOOKUP(Table2[[#This Row],[Invoice Number]],Table4[[Invoice Number]:[Payment Refence]],3) -> 46270 | G16: =VLOOKUP(Table2[[#This Row],[Invoice Number]],Table4[[Invoice Number]:[Payment Refence]],4) -> 2100 | H16: =VLOOKUP(Table2[[#This Row],[Invoice Number]],Table4[[Invoice Number]:[Payment Refence]],5) -> Project delivery | I16: =VLOOKUP(Table2[[#This Row],[Invoice Number]],Table4[[Invoice Number]:[Payment Refence]],6) -> PAY-7005 | J16: =VLOOKUP(Table2[[#This Row],[Invoice Number]],PR!$D$6:$M$110,9) -> 1050 | K16: =CT!K9 -> 1050 | L16: =IF(OR(Table2[[#This Row],[Outstanding Amount]]="Paid All",Table2[[#This Row],[Outstanding Amount]]<1,Table2[[#This Row],[Due Days]]<1,Table2[[#This Row],[Due Days]]=1,Table2[[#This Row],[Due Days]]=""),Table2[[#This Row],[Deposit Amount]],VLOOKUP(Table2[[#This Row],[Due Days]],$Q$8:$R$21,2)*Table2[[#This Row],[Outstanding Amount]]+Table2[[#This Row],[Outstanding Amount]]) -> 1134 | M16: =IF(Table2[[#This Row],[Outstanding Amount]]>1,$F$8-Table2[[#This Row],[Date of invoice]],"") -> 45 | N16: =CT!M9 -> 30 | O16: =IF(OR(Table2[[#This Row],[Days Of Credit]]="",Table2[[#This Row],[Days Of Credit]]=Table2[[#This Row],[Credit Terms]],Table2[[#This Row],[Days Of Credit]]<Table2[[#This Row],[Credit Terms]]),"",Table2[[#This Row],[Days Of Credit]]-Table2[[#This Row],[Credit Terms]]) -> 15 | Q16: =Q15+5 -> 40 | R16: =R15+3% -> 0.23
C17: =C16+1 -> 6 | D17: =PR!D11 -> INV-2026-006 | E17: =VLOOKUP(Table2[[#This Row],[Invoice Number]],Table4[[Invoice Number]:[Payment Refence]],2) -> Ava Robinson | F17: =VLOOKUP(Table2[[#This Row],[Invoice Number]],Table4[[Invoice Number]:[Payment Refence]],3) -> 46275 | G17: =VLOOKUP(Table2[[#This Row],[Invoice Number]],Table4[[Invoice Number]:[Payment Refence]],4) -> 675.8 | H17: =VLOOKUP(Table2[[#This Row],[Invoice Number]],Table4[[Invoice Number]:[Payment Refence]],5) -> Marketing services | I17: =VLOOKUP(Table2[[#This Row],[Invoice Number]],Table4[[Invoice Number]:[Payment Refence]],6) -> PAY-7006 | J17: =VLOOKUP(Table2[[#This Row],[Invoice Number]],PR!$D$6:$M$110,9) -> 337.9 | K17: =CT!K10 -> 337.9 | L17: =IF(OR(Table2[[#This Row],[Outstanding Amount]]="Paid All",Table2[[#This Row],[Outstanding Amount]]<1,Table2[[#This Row],[Due Days]]<1,Table2[[#This Row],[Due Days]]=1,Table2[[#This Row],[Due Days]]=""),Table2[[#This Row],[Deposit Amount]],VLOOKUP(Table2[[#This Row],[Due Days]],$Q$8:$R$21,2)*Table2[[#This Row],[Outstanding Amount]]+Table2[[#This Row],[Outstanding Amount]]) -> 354.795 | M17: =IF(Table2[[#This Row],[Outstanding Amount]]>1,$F$8-Table2[[#This Row],[Date of invoice]],"") -> 40 | N17: =CT!M10 -> 30 | O17: =IF(OR(Table2[[#This Row],[Days Of Credit]]="",Table2[[#This Row],[Days Of Credit]]=Table2[[#This Row],[Credit Terms]],Table2[[#This Row],[Days Of Credit]]<Table2[[#This Row],[Credit Terms]]),"",Table2[[#This Row],[Days Of Credit]]-Table2[[#This Row],[Credit Terms]]) -> 10 | Q17: =Q16+5 -> 45 | R17: =R16+3% -> 0.26
C18: =C17+1 -> 7 | D18: =PR!D12 -> INV-2026-007 | E18: =VLOOKUP(Table2[[#This Row],[Invoice Number]],Table4[[Invoice Number]:[Payment Refence]],2) -> Noah Walker | F18: =VLOOKUP(Table2[[#This Row],[Invoice Number]],Table4[[Invoice Number]:[Payment Refence]],3) -> 46277 | G18: =VLOOKUP(Table2[[#This Row],[Invoice Number]],Table4[[Invoice Number]:[Payment Refence]],4) -> 540 | H18: =VLOOKUP(Table2[[#This Row],[Invoice Number]],Table4[[Invoice Number]:[Payment Refence]],5) -> Maintenance services | I18: =VLOOKUP(Table2[[#This Row],[Invoice Number]],Table4[[Invoice Number]:[Payment Refence]],6) -> PAY-7007 | J18: =VLOOKUP(Table2[[#This Row],[Invoice Number]],PR!$D$6:$M$110,9) -> 540 | K18: =CT!K11 -> Paid All | L18: =IF(OR(Table2[[#This Row],[Outstanding Amount]]="Paid All",Table2[[#This Row],[Outstanding Amount]]<1,Table2[[#This Row],[Due Days]]<1,Table2[[#This Row],[Due Days]]=1,Table2[[#This Row],[Due Days]]=""),Table2[[#This Row],[Deposit Amount]],VLOOKUP(Table2[[#This Row],[Due Days]],$Q$8:$R$21,2)*Table2[[#This Row],[Outstanding Amount]]+Table2[[#This Row],[Outstanding Amount]]) -> 540 | M18: =IF(Table2[[#This Row],[Outstanding Amount]]>1,$F$8-Table2[[#This Row],[Date of invoice]],"") -> 38 | N18: =CT!M11 -> 30 | O18: =IF(OR(Table2[[#This Row],[Days Of Credit]]="",Table2[[#This Row],[Days Of Credit]]=Table2[[#This Row],[Credit Terms]],Table2[[#This Row],[Days Of Credit]]<Table2[[#This Row],[Credit Terms]]),"",Table2[[#This Row],[Days Of Credit]]-Table2[[#This Row],[Credit Terms]]) -> 8 | Q18: =Q17+5 -> 50 | R18: =R17+3% -> 0.29
C19: =C18+1 -> 8 | D19: =PR!D13 -> INV-2026-008 | E19: =VLOOKUP(Table2[[#This Row],[Invoice Number]],Table4[[Invoice Number]:[Payment Refence]],2) -> Grace Hall | F19: =VLOOKUP(Table2[[#This Row],[Invoice Number]],Table4[[Invoice Number]:[Payment Refence]],3) -> 46280 | G19: =VLOOKUP(Table2[[#This Row],[Invoice Number]],Table4[[Invoice Number]:[Payment Refence]],4) -> 1890.75 | H19: =VLOOKUP(Table2[[#This Row],[Invoice Number]],Table4[[Invoice Number]:[Payment Refence]],5) -> Software licence | I19: =VLOOKUP(Table2[[#This Row],[Invoice Number]],Table4[[Invoice Number]:[Payment Refence]],6) -> PAY-7008 | J19: =VLOOKUP(Table2[[#This Row],[Invoice Number]],PR!$D$6:$M$110,9) -> 945.375 | K19: =CT!K12 -> 945.375 | L19: =IF(OR(Table2[[#This Row],[Outstanding Amount]]="Paid All",Table2[[#This Row],[Outstanding Amount]]<1,Table2[[#This Row],[Due Days]]<1,Table2[[#This Row],[Due Days]]=1,Table2[[#This Row],[Due Days]]=""),Table2[[#This Row],[Deposit Amount]],VLOOKUP(Table2[[#This Row],[Due Days]],$Q$8:$R$21,2)*Table2[[#This Row],[Outstanding Amount]]+Table2[[#This Row],[Outstanding Amount]]) -> 964.2825 | M19: =IF(Table2[[#This Row],[Outstanding Amount]]>1,$F$8-Table2[[#This Row],[Date of invoice]],"") -> 35 | N19: =CT!M12 -> 30 | O19: =IF(OR(Table2[[#This Row],[Days Of Credit]]="",Table2[[#This Row],[Days Of Credit]]=Table2[[#This Row],[Credit Terms]],Table2[[#This Row],[Days Of Credit]]<Table2[[#This Row],[Credit Terms]]),"",Table2[[#This Row],[Days Of Credit]]-Table2[[#This Row],[Credit Terms]]) -> 5 | Q19: =Q18+5 -> 55 | R19: =R18+3% -> 0.32
C20: =C19+1 -> 9 | D20: =PR!D14 -> INV-2026-009 | E20: =VLOOKUP(Table2[[#This Row],[Invoice Number]],Table4[[Invoice Number]:[Payment Refence]],2) -> Jack Young | F20: =VLOOKUP(Table2[[#This Row],[Invoice Number]],Table4[[Invoice Number]:[Payment Refence]],3) -> 46283 | G20: =VLOOKUP(Table2[[#This Row],[Invoice Number]],Table4[[Invoice Number]:[Payment Refence]],4) -> 265.5 | H20: =VLOOKUP(Table2[[#This Row],[Invoice Number]],Table4[[Invoice Number]:[Payment Refence]],5) -> Stationery order | I20: =VLOOKUP(Table2[[#This Row],[Invoice Number]],Table4[[Invoice Number]:[Payment Refence]],6) -> PAY-7009 | J20: =VLOOKUP(Table2[[#This Row],[Invoice Number]],PR!$D$6:$M$110,9) -> 265.5 | K20: =CT!K13 -> Paid All | L20: =IF(OR(Table2[[#This Row],[Outstanding Amount]]="Paid All",Table2[[#This Row],[Outstanding Amount]]<1,Table2[[#This Row],[Due Days]]<1,Table2[[#This Row],[Due Days]]=1,Table2[[#This Row],[Due Days]]=""),Table2[[#This Row],[Deposit Amount]],VLOOKUP(Table2[[#This Row],[Due Days]],$Q$8:$R$21,2)*Table2[[#This Row],[Outstanding Amount]]+Table2[[#This Row],[Outstanding Amount]]) -> 265.5 | M20: =IF(Table2[[#This Row],[Outstanding Amount]]>1,$F$8-Table2[[#This Row],[Date of invoice]],"") -> 32 | N20: =CT!M13 -> 30 | O20: =IF(OR(Table2[[#This Row],[Days Of Credit]]="",Table2[[#This Row],[Days Of Credit]]=Table2[[#This Row],[Credit Terms]],Table2[[#This Row],[Days Of Credit]]<Table2[[#This Row],[Credit Terms]]),"",Table2[[#This Row],[Days Of Credit]]-Table2[[#This Row],[Credit Terms]]) -> 2 | Q20: =Q19+5 -> 60 | R20: =R19+3% -> 0.35
C21: =C20+1 -> 10 | D21: =PR!D15 -> INV-2026-010 | E21: =VLOOKUP(Table2[[#This Row],[Invoice Number]],Table4[[Invoice Number]:[Payment Refence]],2) -> Lily Allen | F21: =VLOOKUP(Table2[[#This Row],[Invoice Number]],Table4[[Invoice Number]:[Payment Refence]],3) -> 46285 | G21: =VLOOKUP(Table2[[#This Row],[Invoice Number]],Table4[[Invoice Number]:[Payment Refence]],4) -> 980 | H21: =VLOOKUP(Table2[[#This Row],[Invoice Number]],Table4[[Invoice Number]:[Payment Refence]],5) -> Training services | I21: =VLOOKUP(Table2[[#This Row],[Invoice Number]],Table4[[Invoice Number]:[Payment Refence]],6) -> PAY-7010 | J21: =VLOOKUP(Table2[[#This Row],[Invoice Number]],PR!$D$6:$M$110,9) -> 490 | K21: =CT!K14 -> 490 | L21: =IF(OR(Table2[[#This Row],[Outstanding Amount]]="Paid All",Table2[[#This Row],[Outstanding Amount]]<1,Table2[[#This Row],[Due Days]]<1,Table2[[#This Row],[Due Days]]=1,Table2[[#This Row],[Due Days]]=""),Table2[[#This Row],[Deposit Amount]],VLOOKUP(Table2[[#This Row],[Due Days]],$Q$8:$R$21,2)*Table2[[#This Row],[Outstanding Amount]]+Table2[[#This Row],[Outstanding Amount]]) -> 490 | M21: =IF(Table2[[#This Row],[Outstanding Amount]]>1,$F$8-Table2[[#This Row],[Date of invoice]],"") -> 30 | N21: =CT!M14 -> 30 | O21: =IF(OR(Table2[[#This Row],[Days Of Credit]]="",Table2[[#This Row],[Days Of Credit]]=Table2[[#This Row],[Credit Terms]],Table2[[#This Row],[Days Of Credit]]<Table2[[#This Row],[Credit Terms]]),"",Table2[[#This Row],[Days Of Credit]]-Table2[[#This Row],[Credit Terms]]) | Q21: 70 | R21: =R20+3% -> 0.38
C22: =C21+1 -> 11 | D22: =PR!D16 -> INV-2026-011 | E22: =VLOOKUP(Table2[[#This Row],[Invoice Number]],Table4[[Invoice Number]:[Payment Refence]],2) -> Charlie King | F22: =VLOOKUP(Table2[[#This Row],[Invoice Number]],Table4[[Invoice Number]:[Payment Refence]],3) -> 46287 | G22: =VLOOKUP(Table2[[#This Row],[Invoice Number]],Table4[[Invoice Number]:[Payment Refence]],4) -> 1450 | H22: =VLOOKUP(Table2[[#This Row],[Invoice Number]],Table4[[Invoice Number]:[Payment Refence]],5) -> Consulting services | I22: =VLOOKUP(Table2[[#This Row],[Invoice Number]],Table4[[Invoice Number]:[Payment Refence]],6) -> PAY-7011 | J22: =VLOOKUP(Table2[[#This Row],[Invoice Number]],PR!$D$6:$M$110,9) -> 725 | K22: =CT!K15 -> 725 | L22: =IF(OR(Table2[[#This Row],[Outstanding Amount]]="Paid All",Table2[[#This Row],[Outstanding Amount]]<1,Table2[[#This Row],[Due Days]]<1,Table2[[#This Row],[Due Days]]=1,Table2[[#This Row],[Due Days]]=""),Table2[[#This Row],[Deposit Amount]],VLOOKUP(Table2[[#This Row],[Due Days]],$Q$8:$R$21,2)*Table2[[#This Row],[Outstanding Amount]]+Table2[[#This Row],[Outstanding Amount]]) -> 725 | M22: =IF(Table2[[#This Row],[Outstanding Amount]]>1,$F$8-Table2[[#This Row],[Date of invoice]],"") -> 28 | N22: =CT!M15 -> 30 | O22: =IF(OR(Table2[[#This Row],[Days Of Credit]]="",Table2[[#This Row],[Days Of Credit]]=Table2[[#This Row],[Credit Terms]],Table2[[#This Row],[Days Of Credit]]<Table2[[#This Row],[Credit Terms]]),"",Table2[[#This Row],[Days Of Credit]]-Table2[[#This Row],[Credit Terms]])
C23: =C22+1 -> 12 | D23: =PR!D17 -> INV-2026-012 | E23: =VLOOKUP(Table2[[#This Row],[Invoice Number]],Table4[[Invoice Number]:[Payment Refence]],2) -> Mia Wright | F23: =VLOOKUP(Table2[[#This Row],[Invoice Number]],Table4[[Invoice Number]:[Payment Refence]],3) -> 46290 | G23: =VLOOKUP(Table2[[#This Row],[Invoice Number]],Table4[[Invoice Number]:[Payment Refence]],4) -> 375.25 | H23: =VLOOKUP(Table2[[#This Row],[Invoice Number]],Table4[[Invoice Number]:[Payment Refence]],5) -> Office supplies | I23: =VLOOKUP(Table2[[#This Row],[Invoice Number]],Table4[[Invoice Number]:[Payment Refence]],6) -> PAY-7012 | J23: =VLOOKUP(Table2[[#This Row],[Invoice Number]],PR!$D$6:$M$110,9) -> 187.625 | K23: =CT!K16 -> 187.625 | L23: =IF(OR(Table2[[#This Row],[Outstanding Amount]]="Paid All",Table2[[#This Row],[Outstanding Amount]]<1,Table2[[#This Row],[Due Days]]<1,Table2[[#This Row],[Due Days]]=1,Table2[[#This Row],[Due Days]]=""),Table2[[#This Row],[Deposit Amount]],VLOOKUP(Table2[[#This Row],[Due Days]],$Q$8:$R$21,2)*Table2[[#This Row],[Outstanding Amount]]+Table2[[#This Row],[Outstanding Amount]]) -> 187.625 | M23: =IF(Table2[[#This Row],[Outstanding Amount]]>1,$F$8-Table2[[#This Row],[Date of invoice]],"") -> 25 | N23: =CT!M16 -> 30 | O23: =IF(OR(Table2[[#This Row],[Days Of Credit]]="",Table2[[#This Row],[Days Of Credit]]=Table2[[#This Row],[Credit Terms]],Table2[[#This Row],[Days Of Credit]]<Table2[[#This Row],[Credit Terms]]),"",Table2[[#This Row],[Days Of Credit]]-Table2[[#This Row],[Credit Terms]])
C24: =C23+1 -> 13 | D24: =PR!D18 -> INV-2026-013 | E24: =VLOOKUP(Table2[[#This Row],[Invoice Number]],Table4[[Invoice Number]:[Payment Refence]],2) -> Thomas Scott | F24: =VLOOKUP(Table2[[#This Row],[Invoice Number]],Table4[[Invoice Number]:[Payment Refence]],3) -> 46293 | G24: =VLOOKUP(Table2[[#This Row],[Invoice Number]],Table4[[Invoice Number]:[Payment Refence]],4) -> 2750 | H24: =VLOOKUP(Table2[[#This Row],[Invoice Number]],Table4[[Invoice Number]:[Payment Refence]],5) -> Equipment purchase | I24: =VLOOKUP(Table2[[#This Row],[Invoice Number]],Table4[[Invoice Number]:[Payment Refence]],6) -> PAY-7013 | J24: =VLOOKUP(Table2[[#This Row],[Invoice Number]],PR!$D$6:$M$110,9) -> 1375 | K24: =CT!K17 -> 1375 | L24: =IF(OR(Table2[[#This Row],[Outstanding Amount]]="Paid All",Table2[[#This Row],[Outstanding Amount]]<1,Table2[[#This Row],[Due Days]]<1,Table2[[#This Row],[Due Days]]=1,Table2[[#This Row],[Due Days]]=""),Table2[[#This Row],[Deposit Amount]],VLOOKUP(Table2[[#This Row],[Due Days]],$Q$8:$R$21,2)*Table2[[#This Row],[Outstanding Amount]]+Table2[[#This Row],[Outstanding Amount]]) -> 1375 | M24: =IF(Table2[[#This Row],[Outstanding Amount]]>1,$F$8-Table2[[#This Row],[Date of invoice]],"") -> 22 | N24: =CT!M17 -> 30 | O24: =IF(OR(Table2[[#This Row],[Days Of Credit]]="",Table2[[#This Row],[Days Of Credit]]=Table2[[#This Row],[Credit Terms]],Table2[[#This Row],[Days Of Credit]]<Table2[[#This Row],[Credit Terms]]),"",Table2[[#This Row],[Days Of Credit]]-Table2[[#This Row],[Credit Terms]])
C25: =C24+1 -> 14 | D25: =PR!D19 -> INV-2026-014 | E25: =VLOOKUP(Table2[[#This Row],[Invoice Number]],Table4[[Invoice Number]:[Payment Refence]],2) -> Sophia Green | F25: =VLOOKUP(Table2[[#This Row],[Invoice Number]],Table4[[Invoice Number]:[Payment Refence]],3) -> 46295 | G25: =VLOOKUP(Table2[[#This Row],[Invoice Number]],Table4[[Invoice Number]:[Payment Refence]],4) -> 625 | H25: =VLOOKUP(Table2[[#This Row],[Invoice Number]],Table4[[Invoice Number]:[Payment Refence]],5) -> Monthly subscription | I25: =VLOOKUP(Table2[[#This Row],[Invoice Number]],Table4[[Invoice Number]:[Payment Refence]],6) -> PAY-7014 | J25: =VLOOKUP(Table2[[#This Row],[Invoice Number]],PR!$D$6:$M$110,9) -> 675 | K25: =CT!K18 -> -50 | L25: =IF(OR(Table2[[#This Row],[Outstanding Amount]]="Paid All",Table2[[#This Row],[Outstanding Amount]]<1,Table2[[#This Row],[Due Days]]<1,Table2[[#This Row],[Due Days]]=1,Table2[[#This Row],[Due Days]]=""),Table2[[#This Row],[Deposit Amount]],VLOOKUP(Table2[[#This Row],[Due Days]],$Q$8:$R$21,2)*Table2[[#This Row],[Outstanding Amount]]+Table2[[#This Row],[Outstanding Amount]]) -> 675 | M25: =IF(Table2[[#This Row],[Outstanding Amount]]>1,$F$8-Table2[[#This Row],[Date of invoice]],"") | N25: =CT!M18 -> 30 | O25: =IF(OR(Table2[[#This Row],[Days Of Credit]]="",Table2[[#This Row],[Days Of Credit]]=Table2[[#This Row],[Credit Terms]],Table2[[#This Row],[Days Of Credit]]<Table2[[#This Row],[Credit Terms]]),"",Table2[[#This Row],[Days Of Credit]]-Table2[[#This Row],[Credit Terms]])
C26: =C25+1 -> 15 | D26: =PR!D20 -> INV-2026-015 | E26: =VLOOKUP(Table2[[#This Row],[Invoice Number]],Table4[[Invoice Number]:[Payment Refence]],2) -> Oscar Baker | F26: =VLOOKUP(Table2[[#This Row],[Invoice Number]],Table4[[Invoice Number]:[Payment Refence]],3) -> 46175 | G26: =VLOOKUP(Table2[[#This Row],[Invoice Number]],Table4[[Invoice Number]:[Payment Refence]],4) -> 1120.8 | H26: =VLOOKUP(Table2[[#This Row],[Invoice Number]],Table4[[Invoice Number]:[Payment Refence]],5) -> Project delivery | I26: =VLOOKUP(Table2[[#This Row],[Invoice Number]],Table4[[Invoice Number]:[Payment Refence]],6) -> PAY-7015 | J26: =VLOOKUP(Table2[[#This Row],[Invoice Number]],PR!$D$6:$M$110,9) -> 560.4 | K26: =CT!K19 -> 560.4 | L26: =IF(OR(Table2[[#This Row],[Outstanding Amount]]="Paid All",Table2[[#This Row],[Outstanding Amount]]<1,Table2[[#This Row],[Due Days]]<1,Table2[[#This Row],[Due Days]]=1,Table2[[#This Row],[Due Days]]=""),Table2[[#This Row],[Deposit Amount]],VLOOKUP(Table2[[#This Row],[Due Days]],$Q$8:$R$21,2)*Table2[[#This Row],[Outstanding Amount]]+Table2[[#This Row],[Outstanding Amount]]) -> 773.352 | M26: =IF(Table2[[#This Row],[Outstanding Amount]]>1,$F$8-Table2[[#This Row],[Date of invoice]],"") -> 140 | N26: =CT!M19 -> 30 | O26: =IF(OR(Table2[[#This Row],[Days Of Credit]]="",Table2[[#This Row],[Days Of Credit]]=Table2[[#This Row],[Credit Terms]],Table2[[#This Row],[Days Of Credit]]<Table2[[#This Row],[Credit Terms]]),"",Table2[[#This Row],[Days Of Credit]]-Table2[[#This Row],[Credit Terms]]) -> 110
